Workbook
Name HDFC: Table7[[HDFC Bank ]]
Name HUL: Table7[HUL]
Name Infosys: Table7[Infosys]
Name Market: Table7[Market]
Name Maruti: Table7[Maruti]
Name PortfolioValue: 'Monte Carlo Simulation'!$C$11:$C$10010
Name Return: 'Monte Carlo Simulation'!$B$11:$B$10010
Name SunPharma: Table7[Sun Pharma]

Sheet Problem Statement
A1: Portfolio Analytics, Optimization and Risk Management of an Equity Portfolio Using Microsoft Excel
A3: Problem Statement
A5: The increasing volatility and uncertainty in financial markets make it essential for investors to adopt a systematic approach to portfolio construction and risk management.
A6: Investment decisions based solely on expected returns often ignore diversification, market risk, and potential losses during adverse market conditions.
A7: Consequently, investors require analytical tools that can optimize portfolio allocation, evaluate performance, quantify downside risk, and recommend appropriate hedging strategies.
A8: This project develops an integrated Portfolio Analytics, Optimization, and Risk Management Model using Microsoft Excel for a portfolio consisting of five selected Indian equities.
A9: The project applies quantitative finance techniques to evaluate historical performance, optimize portfolio allocation, simulate future outcomes, measure downside risk, and analyze hedging strategies.
A11: Scope of Work
A13: The project includes the following analyses:
A15: 1 | B15: Historical stock price collection and data preprocessing
A16: 2 | B16: Daily and annual return calculations
A17: 3 | B17: Descriptive statistical analysis (Mean, Median, Standard Deviation, Variance, Skewness and Kurtosis)
A18: 4 | B18: Correlation and Covariance Matrix analysis
A19: 5 | B19: Portfolio return and risk estimation
A20: 6 | B20: Beta estimation for individual stocks and the overall portfolio
A21: 7 | B21: CAPM-based expected return calculation
A22: 8 | B22: Alpha estimation to measure excess returns
A23: 9 | B23: Sharpe Ratio analysis for risk-adjusted performance evaluation
A24: 10 | B24: Portfolio optimization using Modern Portfolio Theory (MPT) and Microsoft Excel Solver
A25: 11 | B25: Monte Carlo Simulation (10,000 simulations) to estimate future portfolio performance
A26: 12 | B26: Parametric and Monte Carlo Value at Risk (VaR) estimation at 95% and 99% confidence levels
... A29: 15 | B29: Executive summary and investment insights based on the analytical findings
A31: Objective
A33: The primary objective of this project is to design an optimized equity portfolio that maximizes risk-adjusted returns while effectively managing downside risk.
A34: By integrating portfolio optimization, simulation techniques, statistical analysis, and hedging strategies into a single Excel-based framework, the project demonstrates
A35: how quantitative financial tools can support informed investment decisions and improve portfolio resilience under varying market conditions.

Sheet Returns
B1: Returns Calculation
B4: Market | C4: Maruti | D4: Sun Pharma | E4: HUL | F4: Infosys | G4: HDFC Bank | I4: CAGR Returns (5 yrs)
B5: -0.0002 | C5: 0.0147 | D5: -0.0007 | E5: -0.002 | F5: 0.0057 | G5: -0.0088
B6: 0.0011 | C6: 0.007 | D6: 0.0046 | E6: -0.0083 | F6: -0.0152 | G6: 0.0075 | I6: Market | J6: =(('Nifty 50'!B2/'Nifty 50'!B1240)^(1/5)-1) -> 0.086170442
B7: -0.0066 | C7: -0.015 | D7: 0.011 | E7: -0.0049 | F7: -0.0088 | G7: -0.0105 | I7: Maruti | J7: =(Maruti!B2/Maruti!B1240)^(1/5)-1 -> 0.13543414
B8: 0.0002 | C8: -0.0115 | D8: -0.0073 | E8: -0.0093 | F8: 0.0324 | G8: -0.0085 | I8: Sun Pharma | J8: =('Sun Pharma'!B2/'Sun Pharma'!B1240)^(1/5)-1 -> 0.23145337
B9: 0.0102 | C9: 0.0092 | D9: -0.0017 | E9: 0.0028 | F9: 0.0164 | G9: 0.0091 | I9: HUL | J9: =(HUL!B2/HUL!B1240)^(1/5)-1 -> -0.027906695
B10: 0.0034 | C10: -0.016 | D10: 0.0267 | E10: 0.0041 | F10: -0.0173 | G10: 0.0089 | I10: Infosys | J10: =(Infosys!B2/Infosys!B1240)^(1/5)-1 -> -0.069949896
B11: -0.0212 | C11: -0.0404 | D11: -0.008 | E11: -0.033 | F11: -0.0023 | G11: -0.0229 | I11: HDFC Bank | J11: =('HDFC Bank'!B2/'HDFC Bank'!B1240)^(1/5)-1 -> 0.012588474
B12: -0.0013 | C12: 0.0057 | D12: -0.0049 | E12: 0.0031 | F12: 0.0284 | G12: -0.0007 | I12: Risk free rate | J12: 0.0675
B13: 0.0066 | C13: 0.0063 | D13: 0.0042 | E13: 0.0004 | F13: -0.0048 | G13: 0.036
B14: 0.0039 | C14: 0.0013 | D14: 0.0181 | E14: -0.0043 | F14: 0.0061 | G14: 0.0065
B15: 0.0071 | C15: -0.0033 | D15: 0.0026 | E15: 0.0131 | F15: 0.0564 | G15: -0.0003
B16: 0.0059 | C16: 0.0198 | D16: 0.002 | E16: 0.0301 | F16: -0.0151 | G16: -0.0023
B17: -0.0034 | C17: 0.0524 | D17: -0.0066 | E17: -0.0154 | F17: -0.035 | G17: -0.0012
B18: -0.0046 | C18: -0.0242 | D18: 0.0064 | E18: -0.0105 | F18: -0.0043 | G18: 0.0033
B19: 0.0014 | C19: 0.0375 | D19: -0.0062 | E19: 0.0076 | F19: -0.0146 | G19: 0.0039
B20: 0.0083 | C20: -0.0151 | D20: 0.0034 | E20: -0.0011 | F20: 0.0265 | G20: 0.0239
B21: -0.0116 | C21: 0.0022 | D21: 0.0027 | E21: -0.0114 | F21: -0.0339 | G21: -0.0149
B22: 0.0037 | C22: 0.0019 | D22: 0.0134 | E22: -0.0044 | F22: 0.0133 | G22: 0.0085
B23: -0.0064 | C23: -0.0066 | D23: 0.0074 | E23: -0.0108 | F23: -0.0675 | G23: -0.024
B24: 0.0034 | C24: -0.0107 | D24: 0.0024 | E24: 0.0095 | F24: -0.0261 | G24: 0.0151
... B1243: -0.0001 | C1243: -0.0005 | D1243: 0.0082 | E1243: 0.0021 | F1243: -0.016 | G1243: 0.0011

Sheet Statistics
A1: Statistical Summary
A3: Statistics | B3: Market | C3: Maruti | D3: Sun Pharma | E3: HUL | F3: Infosys | G3: HDFC Bank
A4: Mean | B4: 0.00037304278 | C4: 0.00062001614 | D4: 0.00093075061 | E4: -3.1557708e-05 | F4: -0.00017522195 | G4: 0.00013712672
A5: Standard Error | B5: 0.00024764641 | C5: 0.00042183372 | D5: 0.00036862112 | E5: 0.00036050201 | F5: 0.00045928986 | G5: 0.0003744103
A6: Median | B6: 0.0005 | C6: 0.0002 | D6: 0.0006 | E6: -0.0004 | F6: -0.0002 | G6: 0.0004
A7: Mode | B7: 0.0014 | C7: -0.0018 | D7: -0.0015 | E7: -0.001 | F7: -0.0027 | G7: 0.0065
A8: Standard Deviation (Annualised) | B8: =0.871701304001829%*SQRT(252) -> 0.13837829 | C8: =1.484830738872%*SQRT(252) -> 0.23570957 | D8: =1.29752541413983%*SQRT(252) -> 0.20597577 | E8: =1.2689466078155%*SQRT(252) -> 0.20143903 | F8: =1.61667419564937%*SQRT(252) -> 0.25663907 | G8: =1.31790298307106%*SQRT(252) -> 0.20921061
A9: Standard Deviation (Daily) | B9: =B8/SQRT(252) -> 0.008717013 | C9: =C8/SQRT(252) -> 0.014848307 | D9: =D8/SQRT(252) -> 0.012975254 | E9: =E8/SQRT(252) -> 0.012689466 | F9: =F8/SQRT(252) -> 0.016166742 | G9: =G8/SQRT(252) -> 0.01317903
A10: Sample Variance | B10: 7.5986316e-05 | C10: 0.00022047223 | D10: 0.00016835722 | E10: 0.00016102255 | F10: 0.00026136355 | G10: 0.00017368683
A11: Kurtosis | B11: 3.7349877 | C11: 3.8193864 | D11: 4.5899239 | E11: 2.304038 | F11: 3.6255004 | G11: 5.6180531
A12: Skewness | B12: -0.39514263 | C12: 0.42456634 | D12: 0.64015946 | E12: 0.22424626 | F12: -0.23779929 | G12: -0.071208586
A13: Range | B13: 0.0975 | C13: 0.1535 | D13: 0.1464 | E13: 0.1176 | F13: 0.1735 | G13: 0.1845
A14: Minimum | B14: -0.0593 | C14: -0.066 | D14: -0.0455 | E14: -0.058 | F14: -0.0942 | G14: -0.0844
A15: Maximum | B15: 0.0382 | C15: 0.0875 | D15: 0.1009 | E15: 0.0596 | F15: 0.0793 | G15: 0.1001
A16: Sum | B16: 0.4622 | C16: 0.7682 | D16: 1.1532 | E16: -0.0391 | F16: -0.2171 | G16: 0.1699
A17: Count | B17: 1239 | C17: 1239 | D17: 1239 | E17: 1239 | F17: 1239 | G17: 1239

Sheet Correlation & Covariance
B2: Correlation Matrix
B4: Particulars | C4: Market | D4: Maruti | E4: Sun Pharma | F4: HUL | G4: Infosys | H4: HDFC Bank
B5: Market | C5: 1 | D5: 0.51236599 | E5: 0.38301643 | F5: 0.37043133 | G5: 0.51310908 | H5: 0.70305388
B6: Maruti | C6: 0.51236599 | D6: 1 | E6: 0.1742077 | F6: 0.28356529 | G6: 0.13848171 | H6: 0.30959183
B7: Sun Pharma | C7: 0.38301643 | D7: 0.1742077 | E7: 1 | F7: 0.1466767 | G7: 0.19215707 | H7: 0.16541624
B8: HUL | C8: 0.37043133 | D8: 0.28356529 | E8: 0.1466767 | F8: 1 | G8: 0.19056642 | H8: 0.21165572
B9: Infosys | C9: 0.51310908 | D9: 0.13848171 | E9: 0.19215707 | F9: 0.19056642 | G9: 1 | H9: 0.24570263
B10: HDFC Bank | C10: 0.70305388 | D10: 0.30959183 | E10: 0.16541624 | F10: 0.21165572 | G10: 0.24570263 | H10: 1
B12: Covariance Matrix
B14: Particulars | C14: Market | D14: Maruti | E14: Sun Pharma | F14: HUL | G14: Infosys | H14: HDFC Bank
B15: Market | C15: =VARP(Returns!$B$5:$B$1243) -> 7.5924988e-05 | D15: 6.6263486e-05 | E15: 4.3286285e-05 | F15: 4.094191e-05 | G15: 7.2251895e-05 | H15: 8.0702889e-05
B16: Maruti | C16: 6.6263486e-05 | D16: =VARP(Returns!$C$5:$C$1243) -> 0.00022029429 | E16: 3.3535866e-05 | F16: 5.3385426e-05 | G16: 3.3215533e-05 | H16: 6.0533978e-05
B17: Sun Pharma | C17: 4.3286285e-05 | D17: 3.3535866e-05 | E17: =VARP(Returns!$D$5:$D$1243) -> 0.00016822134 | F17: 2.4130688e-05 | G17: 4.0275792e-05 | H17: 2.8263556e-05
B18: HUL | C18: 4.094191e-05 | D18: 5.3385426e-05 | E18: 2.4130688e-05 | F18: =VARP(Returns!$E$5:$E$1243) -> 0.00016089259 | G18: 3.9062638e-05 | H18: 3.5367645e-05
B19: Infosys | C19: 7.2251895e-05 | D19: 3.3215533e-05 | E19: 4.0275792e-05 | F19: 3.9062638e-05 | G19: =VARP(Returns!$F$5:$F$1243) -> 0.0002611526 | H19: 5.2307635e-05
B20: HDFC Bank | C20: 8.0702889e-05 | D20: 6.0533978e-05 | E20: 2.8263556e-05 | F20: 3.5367645e-05 | G20: 5.2307635e-05 | H20: =VARP(Returns!$G$5:$G$1243) -> 0.00017354664

Sheet Performance Metrics
B1: Individual Performance Metrics
B3: Particulas | C3: Maruti | D3: Sun Pharma | E3: HUL | F3: Infosys | G3: HDFC Bank
B4: Covariance with Market | C4: =_xlfn.COVARIANCE.P(Market,Maruti) -> 6.6263486e-05 | D4: =_xlfn.COVARIANCE.P(Market,SunPharma) -> 4.3286285e-05 | E4: =_xlfn.COVARIANCE.P(Market,HUL) -> 4.094191e-05 | F4: =_xlfn.COVARIANCE.P(Market,Infosys) -> 7.2251895e-05 | G4: =_xlfn.COVARIANCE.P(Market,HDFC) -> 8.0702889e-05
B5: Variance of Market | C5: =_xlfn.VAR.S(Market) -> 7.5986316e-05 | D5: =C5 -> 7.5986316e-05 | E5: =D5 -> 7.5986316e-05 | F5: =E5 -> 7.5986316e-05 | G5: =F5 -> 7.5986316e-05
B6: Beta of the stocks | C6: =C4/C5 -> 0.87204498 | D6: =D4/D5 -> 0.56965895 | E6: =E4/E5 -> 0.53880635 | F6: =F4/F5 -> 0.95085403 | G6: =G4/G5 -> 1.0620713
B8: Cost of Equity (CAPM) | C8: =Returns!$J$12+(Returns!$J$6-Returns!$J$12)*'Performance Metrics'!C6 -> 0.083781465 | D8: =Returns!$J$12+(Returns!$J$6-Returns!$J$12)*'Performance Metrics'!D6 -> 0.078135784 | E8: =Returns!$J$12+(Returns!$J$6-Returns!$J$12)*'Performance Metrics'!E6 -> 0.077559753 | F8: =Returns!$J$12+(Returns!$J$6-Returns!$J$12)*'Performance Metrics'!F6 -> 0.085252865 | G8: =Returns!$J$12+(Returns!$J$6-Returns!$J$12)*'Performance Metrics'!G6 -> 0.087329342
B9: Actual returns | C9: 0.13543414 | D9: 0.23145337 | E9: -0.027906695 | F9: -0.069949896 | G9: 0.012588474
B10: Alpha | C10: =C9-C8 -> 0.051652679 | D10: =D9-D8 -> 0.15331759 | E10: =E9-E8 -> -0.10546645 | F10: =F9-F8 -> -0.15520276 | G10: =G9-G8 -> -0.074740867
B11: Sharpe | C11: =(C9-Returns!$J$12)/Statistics!C8 -> 0.28821122 | D11: =(D9-Returns!$J$12)/Statistics!D8 -> 0.79598377 | E11: =(E9-Returns!$J$12)/Statistics!E8 -> -0.47362567 | F11: =(F9-Returns!$J$12)/Statistics!F8 -> -0.53557666 | G11: =(G9-Returns!$J$12)/Statistics!G8 -> -0.26247008

Sheet Portfolio Optimizer
B1: Portfolio Optimizer
B3: Investment | C3: 100000000 | D3: (enter investment amount here)
B5: Security | C5: Maruti | D5: Sun Pharma | E5: HUL | F5: Infosys | G5: HDFC Bank
B6: Annual Return | C6: ='Performance Metrics'!C9 -> 0.13543414 | D6: ='Performance Metrics'!D9 -> 0.23145337 | E6: ='Performance Metrics'!E9 -> -0.027906695 | F6: ='Performance Metrics'!F9 -> -0.069949896 | G6: ='Performance Metrics'!G9 -> 0.012588474
B7: Standard deviation | C7: =Statistics!C8 -> 0.23570957 | D7: =Statistics!D8 -> 0.20597577 | E7: =Statistics!E8 -> 0.20143903 | F7: =Statistics!F8 -> 0.25663907 | G7: =Statistics!G8 -> 0.20921061
B8: Minimum Weight | C8: 0.05 | D8: 0.05 | E8: 0.05 | F8: 0.05 | G8: 0.05
B9: Maximum Weight | C9: 0.25 | D9: 0.25 | E9: 0.25 | F9: 0.25 | G9: 0.25
B10: Optimal Weight | C10: 0.25 | D10: 0.25 | E10: 0.2 | F10: 0.05 | G10: 0.25
B11: Investment | C11: =$C$3*C10 -> 25000000 | D11: =$C$3*D10 -> 25000000 | E11: =$C$3*E10 -> 20000000 | F11: =$C$3*F10 -> 5000000 | G11: =$C$3*G10 -> 25000000
B14: Portfolio Summary
B15: Expected Return | C15: =SUMPRODUCT(C6:G6,C10:G10) -> 0.085790164
B16: Standard Deviation | C16: {=SQRT(MMULT(MMULT(C10:G10,'Correlation & Covariance'!D16:H20),TRANSPOSE(C10:G10)*252))} -> 0.13537498
B17: Risk free rate | C17: =Returns!J12 -> 0.0675
B18: Total Weight | C18: =SUM(C10:G10) -> 1
B19: Sharpe | C19: =(C15-C17)/C16 -> 0.13510741
B20: Portfolio Alpha | C20: =SUMPRODUCT(C10:G10,'Performance Metrics'!C10:G10) -> 0.0037039225
B21: Portfolio Beta | C21: =SUMPRODUCT(C10:G10,'Performance Metrics'!C6:G6) -> 0.78124779

Sheet Efficient Frontier
A1: Portfolio | B1: Random Numbers | G1: Weights | L1: Risk & Return
B2: Maruti | C2: Sun Pharma | D2: HUL | E2: Infosys | F2: HDFC Bank | G2: Maruti | H2: Sun Pharma | I2: HUL | J2: Infosys | K2: HDFC Bank | L2: Volatility | M2: Exp return
A3: 1 | B3: =RAND() -> 0.51935209 | C3: =RAND() -> 0.68865022 | D3: =RAND() -> 0.41068978 | E3: =RAND() -> 0.43730741 | F3: =RAND() -> 0.26129634 | G3: =B3/SUM($B3:$F3) -> 0.22411989 | H3: =C3/SUM($B3:$F3) -> 0.29717838 | I3: =D3/SUM($B3:$F3) -> 0.17722803 | J3: =E3/SUM($B3:$F3) -> 0.18871454 | K3: =F3/SUM($B3:$F3) -> 0.11275916 | L3: {=SQRT(MMULT(MMULT(G3:K3,'Correlation & Covariance'!$D$16:$H$20),TRANSPOSE(G3:K3)*252))} -> 0.13494833 | M3: =SUMPRODUCT(G3:K3,'Performance Metrics'!$C$9:$G$9) -> 0.082409479
A4: 2 | B4: =RAND() -> 0.58382446 | C4: =RAND() -> 0.029397049 | D4: =RAND() -> 0.70312286 | E4: =RAND() -> 0.39407183 | F4: =RAND() -> 0.30100153 | G4: =B4/SUM($B4:$F4) -> 0.2902552 | H4: =C4/SUM($B4:$F4) -> 0.014615089 | I4: =D4/SUM($B4:$F4) -> 0.34956581 | J4: =E4/SUM($B4:$F4) -> 0.19591745 | K4: =F4/SUM($B4:$F4) -> 0.14964645 | L4: {=SQRT(MMULT(MMULT(G4:K4,'Correlation & Covariance'!$D$16:$H$20),TRANSPOSE(G4:K4)*252))} -> 0.14638939 | M4: =SUMPRODUCT(G4:K4,'Performance Metrics'!$C$9:$G$9) -> 0.021117365
A5: 3 | B5: =RAND() -> 0.168117 | C5: =RAND() -> 0.090946327 | D5: =RAND() -> 0.71522536 | E5: =RAND() -> 0.17922825 | F5: =RAND() -> 0.025433376 | G5: =B5/SUM($B5:$F5) -> 0.14259889 | H5: =C5/SUM($B5:$F5) -> 0.077141781 | I5: =D5/SUM($B5:$F5) -> 0.60666285 | J5: =E5/SUM($B5:$F5) -> 0.15202358 | K5: =F5/SUM($B5:$F5) -> 0.021572899 | L5: {=SQRT(MMULT(MMULT(G5:K5,'Correlation & Covariance'!$D$16:$H$20),TRANSPOSE(G5:K5)*252))} -> 0.15421191 | M5: =SUMPRODUCT(G5:K5,'Performance Metrics'!$C$9:$G$9) -> 0.0098750645
A6: 4 | B6: =RAND() -> 0.594498 | C6: =RAND() -> 0.21037432 | D6: =RAND() -> 0.9398776 | E6: =RAND() -> 0.41743432 | F6: =RAND() -> 0.12838208 | G6: =B6/SUM($B6:$F6) -> 0.25954193 | H6: =C6/SUM($B6:$F6) -> 0.091843803 | I6: =D6/SUM($B6:$F6) -> 0.41032542 | J6: =E6/SUM($B6:$F6) -> 0.18224066 | K6: =F6/SUM($B6:$F6) -> 0.056048183 | L6: {=SQRT(MMULT(MMULT(G6:K6,'Correlation & Covariance'!$D$16:$H$20),TRANSPOSE(G6:K6)*252))} -> 0.14412984 | M6: =SUMPRODUCT(G6:K6,'Performance Metrics'!$C$9:$G$9) -> 0.032915416
A7: 5 | B7: =RAND() -> 0.60311602 | C7: =RAND() -> 0.10975894 | D7: =RAND() -> 0.63410628 | E7: =RAND() -> 0.71287561 | F7: =RAND() -> 0.95208963 | G7: =B7/SUM($B7:$F7) -> 0.20024128 | H7: =C7/SUM($B7:$F7) -> 0.036441199 | I7: =D7/SUM($B7:$F7) -> 0.2105304 | J7: =E7/SUM($B7:$F7) -> 0.23668269 | K7: =F7/SUM($B7:$F7) -> 0.31610443 | L7: {=SQRT(MMULT(MMULT(G7:K7,'Correlation & Covariance'!$D$16:$H$20),TRANSPOSE(G7:K7)*252))} -> 0.1438408 | M7: =SUMPRODUCT(G7:K7,'Performance Metrics'!$C$9:$G$9) -> 0.01710208
A8: 6 | B8: =RAND() -> 0.82103863 | C8: =RAND() -> 0.75044022 | D8: =RAND() -> 0.57573065 | E8: =RAND() -> 0.2475909 | F8: =RAND() -> 0.44533544 | G8: =B8/SUM($B8:$F8) -> 0.28908428 | H8: =C8/SUM($B8:$F8) -> 0.26422688 | I8: =D8/SUM($B8:$F8) -> 0.20271237 | J8: =E8/SUM($B8:$F8) -> 0.087175724 | K8: =F8/SUM($B8:$F8) -> 0.15680075 | L8: {=SQRT(MMULT(MMULT(G8:K8,'Correlation & Covariance'!$D$16:$H$20),TRANSPOSE(G8:K8)*252))} -> 0.13600373 | M8: =SUMPRODUCT(G8:K8,'Performance Metrics'!$C$9:$G$9) -> 0.090527001
A9: 7 | B9: =RAND() -> 0.81808425 | C9: =RAND() -> 0.15693353 | D9: =RAND() -> 0.73463912 | E9: =RAND() -> 0.3128191 | F9: =RAND() -> 0.45150207 | G9: =B9/SUM($B9:$F9) -> 0.33067563 | H9: =C9/SUM($B9:$F9) -> 0.063433678 | I9: =D9/SUM($B9:$F9) -> 0.2969465 | J9: =E9/SUM($B9:$F9) -> 0.12644376 | K9: =F9/SUM($B9:$F9) -> 0.18250043 | L9: {=SQRT(MMULT(MMULT(G9:K9,'Correlation & Covariance'!$D$16:$H$20),TRANSPOSE(G9:K9)*252))} -> 0.14398901 | M9: =SUMPRODUCT(G9:K9,'Performance Metrics'!$C$9:$G$9) -> 0.044632588
A10: 8 | B10: =RAND() -> 0.96928359 | C10: =RAND() -> 0.21723859 | D10: =RAND() -> 0.68303556 | E10: =RAND() -> 0.8704495 | F10: =RAND() -> 0.73277662 | G10: =B10/SUM($B10:$F10) -> 0.27910853 | H10: =C10/SUM($B10:$F10) -> 0.062554596 | I10: =D10/SUM($B10:$F10) -> 0.19668243 | J10: =E10/SUM($B10:$F10) -> 0.25064891 | K10: =F10/SUM($B10:$F10) -> 0.21100554 | L10: {=SQRT(MMULT(MMULT(G10:K10,'Correlation & Covariance'!$D$16:$H$20),TRANSPOSE(G10:K10)*252))} -> 0.1436708 | M10: =SUMPRODUCT(G10:K10,'Performance Metrics'!$C$9:$G$9) -> 0.031913913
A11: 9 | B11: =RAND() -> 0.8762371 | C11: =RAND() -> 0.58712492 | D11: =RAND() -> 0.40780969 | E11: =RAND() -> 0.93029102 | F11: =RAND() -> 0.97234009 | G11: =B11/SUM($B11:$F11) -> 0.23218942 | H11: =C11/SUM($B11:$F11) -> 0.15557912 | I11: =D11/SUM($B11:$F11) -> 0.10806333 | J11: =E11/SUM($B11:$F11) -> 0.24651288 | K11: =F11/SUM($B11:$F11) -> 0.25765525 | L11: {=SQRT(MMULT(MMULT(G11:K11,'Correlation & Covariance'!$D$16:$H$20),TRANSPOSE(G11:K11)*252))} -> 0.14040392 | M11: =SUMPRODUCT(G11:K11,'Performance Metrics'!$C$9:$G$9) -> 0.050439933
A12: 10 | B12: =RAND() -> 0.29386474 | C12: =RAND() -> 0.19914811 | D12: =RAND() -> 0.76852768 | E12: =RAND() -> 0.67799162 | F12: =RAND() -> 0.77966129 | G12: =B12/SUM($B12:$F12) -> 0.10807055 | H12: =C12/SUM($B12:$F12) -> 0.073237935 | I12: =D12/SUM($B12:$F12) -> 0.28263075 | J12: =E12/SUM($B12:$F12) -> 0.24933556 | K12: =F12/SUM($B12:$F12) -> 0.2867252 | L12: {=SQRT(MMULT(MMULT(G12:K12,'Correlation & Covariance'!$D$16:$H$20),TRANSPOSE(G12:K12)*252))} -> 0.14068203 | M12: =SUMPRODUCT(G12:K12,'Performance Metrics'!$C$9:$G$9) -> 0.0098687562
A13: 11 | B13: =RAND() -> 0.71963041 | C13: =RAND() -> 0.21216167 | D13: =RAND() -> 0.53501702 | E13: =RAND() -> 0.46707978 | F13: =RAND() -> 0.16235009 | G13: =B13/SUM($B13:$F13) -> 0.34329598 | H13: =C13/SUM($B13:$F13) -> 0.10121063 | I13: =D13/SUM($B13:$F13) -> 0.25522711 | J13: =E13/SUM($B13:$F13) -> 0.222818 | K13: =F13/SUM($B13:$F13) -> 0.077448274 | L13: {=SQRT(MMULT(MMULT(G13:K13,'Correlation & Covariance'!$D$16:$H$20),TRANSPOSE(G13:K13)*252))} -> 0.14489468 | M13: =SUMPRODUCT(G13:K13,'Performance Metrics'!$C$9:$G$9) -> 0.048185853
A14: 12 | B14: =RAND() -> 0.74427889 | C14: =RAND() -> 0.99314873 | D14: =RAND() -> 0.36634016 | E14: =RAND() -> 0.37642489 | F14: =RAND() -> 0.54615223 | G14: =B14/SUM($B14:$F14) -> 0.24593327 | H14: =C14/SUM($B14:$F14) -> 0.32816773 | I14: =D14/SUM($B14:$F14) -> 0.12105037 | J14: =E14/SUM($B14:$F14) -> 0.12438268 | K14: =F14/SUM($B14:$F14) -> 0.18046596 | L14: {=SQRT(MMULT(MMULT(G14:K14,'Correlation & Covariance'!$D$16:$H$20),TRANSPOSE(G14:K14)*252))} -> 0.13573437 | M14: =SUMPRODUCT(G14:K14,'Performance Metrics'!$C$9:$G$9) -> 0.099456409
... A102: 100 | B102: =RAND() -> 0.12186866 | C102: =RAND() -> 0.48817479 | D102: =RAND() -> 0.58698584 | E102: =RAND() -> 0.66189149 | F102: =RAND() -> 0.77847171 | G102: =B102/SUM($B102:$F102) -> 0.046208012 | H102: =C102/SUM($B102:$F102) -> 0.18509751 | I102: =D102/SUM($B102:$F102) -> 0.22256295 | J102: =E102/SUM($B102:$F102) -> 0.25096435 | K102: =F102/SUM($B102:$F102) -> 0.29516718 | L102: {=SQRT(MMULT(MMULT(G102:K102,'Correlation & Covariance'!$D$16:$H$20),TRANSPOSE(G102:K102)*252))} -> 0.13788316 | M102: =SUMPRODUCT(G102:K102,'Performance Metrics'!$C$9:$G$9) -> 0.029049364

Sheet Monte Carlo Simulation
A1: Monte Carlo Simulation (Yearly)
A3: Input | B3: Value | K3: Metric | L3: Value / % | N3: Return Range | O3: No of times | P3: % of times
A4: Initial Investment | B4: ='Portfolio Optimizer'!C3 -> 100000000 | K4: Number of Simulations | L4: =COUNT(B11:B10010) -> 10000 | N4: Below -50% | O4: =COUNTIF($B$11:$B$10010,"<-50%") -> 0 | P4: =O4/$O$26 -> 0
A5: Expected Return | B5: ='Portfolio Optimizer'!C15 -> 0.085790164 | K5: Average Simulated Return | L5: =AVERAGE(B11:B10010) -> 0.086473032 | N5: -50% to -45% | O5: =COUNTIFS($B$11:$B$10010,">=-50%",$B$11:$B$10010,"<-45%") -> 1 | P5: =O5/$O$26 -> 0.0001
A6: Portfolio Std Dev | B6: ='Portfolio Optimizer'!C16 -> 0.13537498 | K6: Median Return | L6: =MEDIAN(B11:B10010) -> 0.087636892 | N6: -45% to -40% | O6: =COUNTIFS($B$11:$B$10010,">=-45%",$B$11:$B$10010,"<-40%") -> 2 | P6: =O6/$O$26 -> 0.0002
A7: Simulations | B7: 10000 | K7: Standard Deviation | L7: =_xlfn.STDEV.S(B11:B10010) -> 0.13644932 | N7: -40% to -35% | O7: =COUNTIFS($B$11:$B$10010,">=-40%",$B$11:$B$10010,"<-35%") -> 4 | P7: =O7/$O$26 -> 0.0004
A8: Days | B8: 252 | K8: Minimum Return | L8: =MIN(B11:B10010) -> -0.45955914 | N8: -35% to -30% | O8: =COUNTIFS($B$11:$B$10010,">=-35%",$B$11:$B$10010,"<-30%") -> 19 | P8: =O8/$O$26 -> 0.0019
K9: Maximum Return | L9: =MAX(B11:B10010) -> 0.63675798 | N9: -30% to -25% | O9: =COUNTIFS($B$11:$B$10010,">=-30%",$B$11:$B$10010,"<-25%") -> 43 | P9: =O9/$O$26 -> 0.0043
A10: Iternations | B10: Return | C10: Portfolio Value (₹) | K10: 5th Percentile | L10: =_xlfn.PERCENTILE.INC(B11:B10010,0.05) -> -0.1399394 | N10: -25% to -20% | O10: =COUNTIFS($B$11:$B$10010,">=-25%",$B$11:$B$10010,"<-20%") -> 113 | P10: =O10/$O$26 -> 0.0113
A11: 1 | B11: 0.10521215 | C11: =$B$4*(1+B11) -> 1.1052121e+08 | K11: 95th Percentile | L11: =_xlfn.PERCENTILE.INC(B11:B10010,0.95) -> 0.30980714 | N11: -20% to -15% | O11: =COUNTIFS($B$11:$B$10010,">=-20%",$B$11:$B$10010,"<-15%") -> 241 | P11: =O11/$O$26 -> 0.0241
A12: 2 | B12: 0.1598598 | C12: =$B$4*(1+B12) -> 1.1598598e+08 | N12: -15% to -10% | O12: =COUNTIFS($B$11:$B$10010,">=-15%",$B$11:$B$10010,"<-10%") -> 443 | P12: =O12/$O$26 -> 0.0443
A13: 3 | B13: 0.0053485433 | C13: =$B$4*(1+B13) -> 1.0053485e+08 | K13: Metric | L13: Value / % | N13: -10% to -5% | O13: =COUNTIFS($B$11:$B$10010,">=-10%",$B$11:$B$10010,"<-5%") -> 712 | P13: =O13/$O$26 -> 0.0712
A14: 4 | B14: 0.13536594 | C14: =$B$4*(1+B14) -> 1.1353659e+08 | K14: Probability of Positive | L14: =COUNTIF(B9:B10008,">0")/COUNT(B9:B10008) -> 0.73434687 | N14: -5% to 0% | O14: =COUNTIFS($B$11:$B$10010,">=-5%",$B$11:$B$10010,"<0%") -> 1079 | P14: =O14/$O$26 -> 0.1079
A15: 5 | B15: -0.014283005 | C15: =$B$4*(1+B15) -> 98571699 | K15: Probability of Negative | L15: =COUNTIF(B9:B10008,"<0")/COUNT(B9:B10008) -> 0.26565313 | N15: 0% to 5% | O15: =COUNTIFS($B$11:$B$10010,">=0%",$B$11:$B$10010,"<5%") -> 1273 | P15: =O15/$O$26 -> 0.1273
A16: 6 | B16: -0.098449093 | C16: =$B$4*(1+B16) -> 90155091 | K16: Probability of Return >10% | L16: =COUNTIF(B11:B10010,">10%")/COUNT(B11:B10010) -> 0.4667 | N16: 5% to 10% | O16: =COUNTIFS($B$11:$B$10010,">=5%",$B$11:$B$10010,"<10%") -> 1403 | P16: =O16/$O$26 -> 0.1403
A17: 7 | B17: 0.14216646 | C17: =$B$4*(1+B17) -> 1.1421665e+08 | K17: Probability of Return >20% | L17: =COUNTIF(B11:B10010,">20%")/COUNT(B11:B10010) -> 0.2044 | N17: 10% to 15% | O17: =COUNTIFS($B$11:$B$10010,">=10%",$B$11:$B$10010,"<15%") -> 1448 | P17: =O17/$O$26 -> 0.1448
A18: 8 | B18: 0.036771117 | C18: =$B$4*(1+B18) -> 1.0367711e+08 | K18: Probability of Return >30% | L18: =COUNTIF(B11:B10010,">30%")/COUNT(B11:B10010) -> 0.0574 | N18: 15% to 20% | O18: =COUNTIFS($B$11:$B$10010,">=15%",$B$11:$B$10010,"<20%") -> 1175 | P18: =O18/$O$26 -> 0.1175
A19: 9 | B19: 0.23861482 | C19: =$B$4*(1+B19) -> 1.2386148e+08 | K19: Probability of Loss >10% | L19: =COUNTIF(B11:B10010,"<-10%")/COUNT(B11:B10010) -> 0.0866 | N19: 20% to 25% | O19: =COUNTIFS($B$11:$B$10010,">=20%",$B$11:$B$10010,"<25%") -> 885 | P19: =O19/$O$26 -> 0.0885
A20: 10 | B20: 0.2352899 | C20: =$B$4*(1+B20) -> 1.2352899e+08 | K20: Probability of Loss >20% | L20: =COUNTIF(B11:B10010,"<-20%")/COUNT(B11:B10010) -> 0.0182 | N20: 25% to 30% | O20: =COUNTIFS($B$11:$B$10010,">=25%",$B$11:$B$10010,"<30%") -> 585 | P20: =O20/$O$26 -> 0.0585
A21: 11 | B21: 0.18228106 | C21: =$B$4*(1+B21) -> 1.1822811e+08 | K21: Probability of Loss >30% | L21: =COUNTIF(B11:B10010,"<-30%")/COUNT(B11:B10010) -> 0.0026 | N21: 30% to 35% | O21: =COUNTIFS($B$11:$B$10010,">=30%",$B$11:$B$10010,"<35%") -> 328 | P21: =O21/$O$26 -> 0.0328
A22: 12 | B22: -0.10398468 | C22: =$B$4*(1+B22) -> 89601532 | N22: 35% to 40% | O22: =COUNTIFS($B$11:$B$10010,">=35%",$B$11:$B$10010,"<40%") -> 154 | P22: =O22/$O$26 -> 0.0154
A23: 13 | B23: 0.029963762 | C23: =$B$4*(1+B23) -> 1.0299638e+08 | K23: Metric | L23: Value / % | N23: 40% to 45% | O23: =COUNTIFS($B$11:$B$10010,">=40%",$B$11:$B$10010,"<45%") -> 58 | P23: =O23/$O$26 -> 0.0058
A24: 14 | B24: 0.32489143 | C24: =$B$4*(1+B24) -> 1.3248914e+08 | K24: Expected Portfolio Value | L24: =$B$4*(1+AVERAGE(B11:B10010)) -> 1.086473e+08 | N24: 45% to 50% | O24: =COUNTIFS($B$11:$B$10010,">=45%",$B$11:$B$10010,"<50%") -> 24 | P24: =O24/$O$26 -> 0.0024
A25: 15 | B25: 0.2837996 | C25: =$B$4*(1+B25) -> 1.2837996e+08 | K25: Worst Simulated Value | L25: =$B$4*(1+MIN(B11:B10010)) -> 54044086 | N25: Above 50% | O25: =COUNTIF($B$11:$B$10010,">=50%") -> 10 | P25: =O25/$O$26 -> 0.001
A26: 16 | B26: 0.22346204 | C26: =$B$4*(1+B26) -> 1.223462e+08 | K26: Best Simulated Value | L26: =$B$4*(1+MAX(B11:B10010)) -> 1.636758e+08 | N26: Total | O26: =SUM(O4:O25) -> 10000 | P26: =SUM(P4:P25) -> 1
A27: 17 | B27: -0.078626712 | C27: =$B$4*(1+B27) -> 92137329 | K27: 5% Worst Case Value | L27: =$B$4*(1+_xlfn.PERCENTILE.INC(B11:B10010,0.05)) -> 86006060
A28: 18 | B28: 0.053044387 | C28: =$B$4*(1+B28) -> 1.0530444e+08 | K28: 95% Best Case Value | L28: =$B$4*(1+_xlfn.PERCENTILE.INC(B11:B10010,0.95)) -> 1.3098071e+08
A29: 19 | B29: 0.1436005 | C29: =$B$4*(1+B29) -> 1.1436005e+08
A30: 20 | B30: -0.071058922 | C30: =$B$4*(1+B30) -> 92894108
A31: 21 | B31: 0.073018208 | C31: =$B$4*(1+B31) -> 1.0730182e+08
A32: 22 | B32: 0.28228612 | C32: =$B$4*(1+B32) -> 1.2822861e+08
A33: 23 | B33: 0.061589667 | C33: =$B$4*(1+B33) -> 1.0615897e+08
A34: 24 | B34: 0.23767628 | C34: =$B$4*(1+B34) -> 1.2376763e+08
A35: 25 | B35: 0.088967416 | C35: =$B$4*(1+B35) -> 1.0889674e+08
A36: 26 | B36: 0.059659093 | C36: =$B$4*(1+B36) -> 1.0596591e+08
A37: 27 | B37: -0.038938522 | C37: =$B$4*(1+B37) -> 96106148
A38: 28 | B38: 0.27091795 | C38: =$B$4*(1+B38) -> 1.2709179e+08
A39: 29 | B39: -0.29466718 | C39: =$B$4*(1+B39) -> 70533282
A40: 30 | B40: -0.02071706 | C40: =$B$4*(1+B40) -> 97928294
... A10010: 10000 | B10010: -0.12914674 | C10010: =$B$4*(1+B10010) -> 87085326

Sheet Risk Analysis and Hedging
A1: Portfolio Hedging Analysis | I1: MONTE CARLO VAR | L1: PARAMETRIC VAR
A3: Index futures values are assumed to be taken as on date of calculation, Values may differ later | I3: Confidence Level | J3: Return VaR | K3: ₹ VaR | L3: Confidence Level | M3: Return VAR | N3: ₹ VAR
I4: 0.95 | J4: =_xlfn.PERCENTILE.INC(Return,0.05) -> -0.1399394 | K4: =ABS('Monte Carlo Simulation'!$B$4*J4) -> 13993940 | L4: 0.95 | M4: ='Monte Carlo Simulation'!B5-(1.645*'Monte Carlo Simulation'!B6) -> -0.13690168 | N4: =ABS('Monte Carlo Simulation'!$B$4*M4) -> 13690168
I5: 0.99 | J5: =_xlfn.PERCENTILE.INC(Return,0.01) -> -0.2316935 | K5: =ABS('Monte Carlo Simulation'!B4*J5) -> 23169350 | L5: 0.99 | M5: ='Monte Carlo Simulation'!B5-(2.326*'Monte Carlo Simulation'!B6) -> -0.22909205 | N5: =ABS('Monte Carlo Simulation'!$B$4*M5) -> 22909205
B7: Contract Details | I7: Stress Test Scenarios
B8: Index | C8: Nifty | I8: Scenario | J8: Market Return | K8: Portfolio Return | L8: Portfolio Value | M8: Portfolio Loss (₹)
B9: Security Type | C9: Futures | I9: Mild Correction | J9: -0.1 | K9: =J9*'Portfolio Optimizer'!$C$21 -> -0.078124779 | L9: ='Monte Carlo Simulation'!$B$4*(1+'Risk Analysis and Hedging'!K9) -> 92187522 | M9: =L9-'Monte Carlo Simulation'!$B$4 -> -7812477.9
B10: Name of Security | C10: Nifty 28 Jul Fut | I10: Bear Market | J10: -0.2 | K10: =J10*'Portfolio Optimizer'!$C$21 -> -0.15624956 | L10: ='Monte Carlo Simulation'!$B$4*(1+'Risk Analysis and Hedging'!K10) -> 84375044 | M10: =L10-'Monte Carlo Simulation'!$B$4 -> -15624956
B11: CMP (Close on 17/7/26) | C11: 24345 | I11: Market Crash | J11: -0.3 | K11: =J11*'Portfolio Optimizer'!$C$21 -> -0.23437434 | L11: ='Monte Carlo Simulation'!$B$4*(1+'Risk Analysis and Hedging'!K11) -> 76562566 | M11: =L11-'Monte Carlo Simulation'!$B$4 -> -23437434
B12: Contract Size | C12: 65 | I12: Financial Crisis | J12: -0.4 | K12: =J12*'Portfolio Optimizer'!$C$21 -> -0.31249912 | L12: ='Monte Carlo Simulation'!$B$4*(1+'Risk Analysis and Hedging'!K12) -> 68750088 | M12: =L12-'Monte Carlo Simulation'!$B$4 -> -31249912
B13: Contract Value | C13: =C11*C12 -> 1582425 | I13: Black Swan | J13: -0.5 | K13: =J13*'Portfolio Optimizer'!$C$21 -> -0.39062389 | L13: ='Monte Carlo Simulation'!$B$4*(1+'Risk Analysis and Hedging'!K13) -> 60937611 | M13: =L13-'Monte Carlo Simulation'!$B$4 -> -39062389
B15: No of contracts for Hedging | I15: Hedge Values
B16: Scenario | C16: Hedge Ratios | I16: Scenario | J16: Hedge Ratios
C17: 1 | D17: 0.75 | E17: 0.5 | F17: 0.25 | J17: 1 | K17: 0.75 | L17: 0.5 | M17: 0.25
B18: =I18 -> Mild Correction | C18: =('Monte Carlo Simulation'!B4*'Risk Analysis and Hedging'!C17)/'Risk Analysis and Hedging'!C13 -> 63.194148 | D18: =('Monte Carlo Simulation'!$B$4*'Risk Analysis and Hedging'!D$17)/$C$13 -> 47.395611 | E18: =('Monte Carlo Simulation'!$B$4*'Risk Analysis and Hedging'!E$17)/$C$13 -> 31.597074 | F18: =('Monte Carlo Simulation'!$B$4*'Risk Analysis and Hedging'!F$17)/$C$13 -> 15.798537 | I18: =I9 -> Mild Correction | J18: =ABS($M9)*J$17 -> 7812477.9 | K18: =ABS($M9)*K$17 -> 5859358.4 | L18: =ABS($M9)*L$17 -> 3906238.9 | M18: =ABS($M9)*M$17 -> 1953119.5
B19: =I19 -> Bear Market | C19: =('Monte Carlo Simulation'!$B$4*$C$17)/$C$13 -> 63.194148 | D19: =('Monte Carlo Simulation'!$B$4*'Risk Analysis and Hedging'!D$17)/$C$13 -> 47.395611 | E19: =('Monte Carlo Simulation'!$B$4*'Risk Analysis and Hedging'!E$17)/$C$13 -> 31.597074 | F19: =('Monte Carlo Simulation'!$B$4*'Risk Analysis and Hedging'!F$17)/$C$13 -> 15.798537 | I19: =I10 -> Bear Market | J19: =ABS($M10)*J$17 -> 15624956 | K19: =ABS($M10)*K$17 -> 11718717 | L19: =ABS($M10)*L$17 -> 7812477.9 | M19: =ABS($M10)*M$17 -> 3906238.9
B20: =I20 -> Market Crash | C20: =('Monte Carlo Simulation'!$B$4*$C$17)/$C$13 -> 63.194148 | D20: =('Monte Carlo Simulation'!$B$4*'Risk Analysis and Hedging'!D$17)/$C$13 -> 47.395611 | E20: =('Monte Carlo Simulation'!$B$4*'Risk Analysis and Hedging'!E$17)/$C$13 -> 31.597074 | F20: =('Monte Carlo Simulation'!$B$4*'Risk Analysis and Hedging'!F$17)/$C$13 -> 15.798537 | I20: =I11 -> Market Crash | J20: =ABS($M11)*J$17 -> 23437434 | K20: =ABS($M11)*K$17 -> 17578075 | L20: =ABS($M11)*L$17 -> 11718717 | M20: =ABS($M11)*M$17 -> 5859358.4
B21: =I21 -> Financial Crisis | C21: =('Monte Carlo Simulation'!$B$4*$C$17)/$C$13 -> 63.194148 | D21: =('Monte Carlo Simulation'!$B$4*'Risk Analysis and Hedging'!D$17)/$C$13 -> 47.395611 | E21: =('Monte Carlo Simulation'!$B$4*'Risk Analysis and Hedging'!E$17)/$C$13 -> 31.597074 | F21: =('Monte Carlo Simulation'!$B$4*'Risk Analysis and Hedging'!F$17)/$C$13 -> 15.798537 | I21: =I12 -> Financial Crisis | J21: =ABS($M12)*J$17 -> 31249912 | K21: =ABS($M12)*K$17 -> 23437434 | L21: =ABS($M12)*L$17 -> 15624956 | M21: =ABS($M12)*M$17 -> 7812477.9
B22: =I22 -> Black Swan | C22: =('Monte Carlo Simulation'!$B$4*$C$17)/$C$13 -> 63.194148 | D22: =('Monte Carlo Simulation'!$B$4*'Risk Analysis and Hedging'!D$17)/$C$13 -> 47.395611 | E22: =('Monte Carlo Simulation'!$B$4*'Risk Analysis and Hedging'!E$17)/$C$13 -> 31.597074 | F22: =('Monte Carlo Simulation'!$B$4*'Risk Analysis and Hedging'!F$17)/$C$13 -> 15.798537 | I22: =I13 -> Black Swan | J22: =ABS($M13)*J$17 -> 39062389 | K22: =ABS($M13)*K$17 -> 29296792 | L22: =ABS($M13)*L$17 -> 19531195 | M22: =ABS($M13)*M$17 -> 9765597.4
B25: Alternatively, put option can also be considered for low cost hedging

Sheet MCS(Daily)
A1: Input | B1: Value
A2: Initial Investment | B2: 100000
A3: Expected Return | B3: =(1+'Monte Carlo Simulation'!B5)^(1/252)-1 -> 0.00032667233
A4: Portfolio Std Dev | B4: ='Portfolio Optimizer'!C16/SQRT(252) -> 0.0085278224
A5: Simulations | B5: 10000
A6: Days | B6: 252
A8: Iternations | B8: Value
A9: 1 | B9: =_xlfn.NORM.INV(RAND(),$B$3,$B$4) -> 0.0090083956
A10: 2 | B10: =_xlfn.NORM.INV(RAND(),$B$3,$B$4) -> -0.0081103269
A11: 3 | B11: =_xlfn.NORM.INV(RAND(),$B$3,$B$4) -> -0.014605429
A12: 4 | B12: =_xlfn.NORM.INV(RAND(),$B$3,$B$4) -> 0.0070769992
A13: 5 | B13: =_xlfn.NORM.INV(RAND(),$B$3,$B$4) -> 0.0021733182
A14: 6 | B14: =_xlfn.NORM.INV(RAND(),$B$3,$B$4) -> -0.0089650385
A15: 7 | B15: =_xlfn.NORM.INV(RAND(),$B$3,$B$4) -> -0.0031826479
A16: 8 | B16: =_xlfn.NORM.INV(RAND(),$B$3,$B$4) -> -0.02144353
A17: 9 | B17: =_xlfn.NORM.INV(RAND(),$B$3,$B$4) -> 0.0097559761
A18: 10 | B18: =_xlfn.NORM.INV(RAND(),$B$3,$B$4) -> 0.0024557422
A19: 11 | B19: =_xlfn.NORM.INV(RAND(),$B$3,$B$4) -> 0.0082435965
A20: 12 | B20: =_xlfn.NORM.INV(RAND(),$B$3,$B$4) -> 0.0041349226
... A10008: 10000 | B10008: =_xlfn.NORM.INV(RAND(),$B$3,$B$4) -> 0.007223107

Sheet Maruti
A1: Date | B1: Price | C1: Open | D1: High | E1: Low | F1: Vol. | G1: Change %
A2: 07/16/2026 | B2: 13783 | C2: 13605 | D2: 13845 | E2: 13584 | F2: 356.85K | G2: 0.0147
A3: 07/15/2026 | B3: 13583 | C3: 13503 | D3: 13606 | E3: 13435 | F3: 456.37K | G3: 0.007
A4: 07/14/2026 | B4: 13489 | C4: 13619 | D4: 13690 | E4: 13470 | F4: 368.65K | G4: -0.015
A5: 07/13/2026 | B5: 13695 | C5: 13682 | D5: 13841 | E5: 13536 | F5: 458.63K | G5: -0.0115
A6: 46302 | B6: 13854 | C6: 13800 | D6: 13987 | E6: 13776 | F6: 430.15K | G6: 0.0092
A7: 46272 | B7: 13728 | C7: 14000 | D7: 14037 | E7: 13700 | F7: 576.45K | G7: -0.016
A8: 46241 | B8: 13951 | C8: 14475 | D8: 14500 | E8: 13880 | F8: 481.08K | G8: -0.0404
A9: 46210 | B9: 14538 | C9: 14463 | D9: 14598 | E9: 14414 | F9: 524.76K | G9: 0.0057
A10: 46180 | B10: 14456 | C10: 14348 | D10: 14526 | E10: 14291 | F10: 214.69K | G10: 0.0063
A11: 46088 | B11: 14366 | C11: 14450 | D11: 14520 | E11: 14333 | F11: 384.19K | G11: 0.0013
A12: 46060 | B12: 14348 | C12: 14431 | D12: 14490 | E12: 14275 | F12: 327.09K | G12: -0.0033
A13: 46029 | B13: 14395 | C13: 14151 | D13: 14549 | E13: 14070 | F13: 1.40M | G13: 0.0198
A14: 06/30/2026 | B14: 14115 | C14: 13744 | D14: 14201 | E14: 13510 | F14: 1.51M | G14: 0.0524
A15: 06/29/2026 | B15: 13412 | C15: 13740 | D15: 13840 | E15: 13371 | F15: 1.36M | G15: -0.0242
A16: 06/25/2026 | B16: 13745 | C16: 13358 | D16: 13917 | E16: 13326 | F16: 981.56K | G16: 0.0375
A17: 06/24/2026 | B17: 13248 | C17: 13440 | D17: 13440 | E17: 13201 | F17: 327.50K | G17: -0.0151
A18: 06/23/2026 | B18: 13451 | C18: 13420 | D18: 13549 | E18: 13236 | F18: 398.56K | G18: 0.0022
A19: 06/22/2026 | B19: 13421 | C19: 13450 | D19: 13495 | E19: 13380 | F19: 254.53K | G19: 0.0019
A20: 06/19/2026 | B20: 13395 | C20: 13484 | D20: 13507 | E20: 13353 | F20: 719.76K | G20: -0.0066
A21: 06/18/2026 | B21: 13484 | C21: 13646 | D21: 13714 | E21: 13433 | F21: 373.51K | G21: -0.0107
A22: 06/17/2026 | B22: 13630 | C22: 13700 | D22: 13740 | E22: 13560 | F22: 241.53K | G22: -0.0045
A23: 06/16/2026 | B23: 13691 | C23: 13861 | D23: 13874 | E23: 13661 | F23: 280.51K | G23: -0.0083
A24: 06/15/2026 | B24: 13805 | C24: 13550 | D24: 13961 | E24: 13520 | F24: 613.28K | G24: 0.0328
A25: 46362 | B25: 13366 | C25: 13232 | D25: 13418 | E25: 13130 | F25: 559.04K | G25: 0.0205
A26: 46332 | B26: 13098 | C26: 13070 | D26: 13217 | E26: 12968 | F26: 308.71K | G26: 0.0019
A27: 46301 | B27: 13073 | C27: 13118 | D27: 13205 | E27: 13050 | F27: 203.89K | G27: -0.0036
A28: 46271 | B28: 13120 | C28: 13079 | D28: 13157 | E28: 12851 | F28: 428.32K | G28: 0.0161
A29: 46240 | B29: 12912 | C29: 12900 | D29: 13029 | E29: 12841 | F29: 372.90K | G29: -0.0106
A30: 46148 | B30: 13050 | C30: 13151 | D30: 13175 | E30: 12915 | F30: 295.70K | G30: -0.0011
A31: 46118 | B31: 13064 | C31: 12990 | D31: 13264 | E31: 12949 | F31: 465.07K | G31: 0.0015
A32: 46087 | B32: 13044 | C32: 13014 | D32: 13206 | E32: 12911 | F32: 607.81K | G32: 0.0017
A33: 46059 | B33: 13022 | C33: 12700 | D33: 13051 | E33: 12700 | F33: 586.60K | G33: 0.0059
A34: 46028 | B34: 12946 | C34: 13200 | D34: 13267 | E34: 12913 | F34: 295.36K | G34: -0.0138
A35: 05/29/2026 | B35: 13127 | C35: 13456 | D35: 13508 | E35: 13050 | F35: 963.29K | G35: -0.0177
A36: 05/27/2026 | B36: 13364 | C36: 13208 | D36: 13417 | E36: 13102 | F36: 322.02K | G36: 0.0118
A37: 05/26/2026 | B37: 13208 | C37: 13188 | D37: 13329 | E37: 13134 | F37: 256.90K | G37: 0.0029
A38: 05/25/2026 | B38: 13170 | C38: 13145 | D38: 13236 | E38: 13101 | F38: 276.55K | G38: 0.0141
A39: 05/22/2026 | B39: 12987 | C39: 13100 | D39: 13152 | E39: 12974 | F39: 387.98K | G39: -0.0018
A40: 05/21/2026 | B40: 13010 | C40: 13103 | D40: 13150 | E40: 12933 | F40: 213.10K | G40: 0.0005
...

Sheet Sun Pharma
A1: Date | B1: Price | C1: Open | D1: High | E1: Low | F1: Vol. | G1: Change %
A2: 07/16/2026 | B2: 1950.1 | C2: 1950 | D2: 1957.7 | E2: 1943 | F2: 1.40M | G2: -0.0007
A3: 07/15/2026 | B3: 1951.5 | C3: 1955 | D3: 1962.7 | E3: 1943.3 | F3: 2.28M | G3: 0.0046
A4: 07/14/2026 | B4: 1942.6 | C4: 1910 | D4: 1950.8 | E4: 1910 | F4: 2.82M | G4: 0.011
A5: 07/13/2026 | B5: 1921.4 | C5: 1925.9 | D5: 1933.1 | E5: 1911 | F5: 1.57M | G5: -0.0073
A6: 46302 | B6: 1935.5 | C6: 1942.8 | D6: 1953.9 | E6: 1926.6 | F6: 1.48M | G6: -0.0017
A7: 46272 | B7: 1938.7 | C7: 1889.9 | D7: 1952 | E7: 1888.2 | F7: 4.45M | G7: 0.0267
A8: 46241 | B8: 1888.2 | C8: 1904 | D8: 1929.5 | E8: 1875.1 | F8: 2.79M | G8: -0.008
A9: 46210 | B9: 1903.4 | C9: 1900.6 | D9: 1924.9 | E9: 1898.6 | F9: 2.06M | G9: -0.0049
A10: 46180 | B10: 1912.8 | C10: 1904 | D10: 1917 | E10: 1900 | F10: 1.21M | G10: 0.0042
A11: 46088 | B11: 1904.8 | C11: 1880 | D11: 1925.1 | E11: 1871.6 | F11: 2.17M | G11: 0.0181
A12: 46060 | B12: 1871 | C12: 1876 | D12: 1882 | E12: 1868.3 | F12: 1.49M | G12: 0.0026
A13: 46029 | B13: 1866.2 | C13: 1877.9 | D13: 1887.4 | E13: 1860.2 | F13: 1.23M | G13: 0.002
A14: 06/30/2026 | B14: 1862.5 | C14: 1885 | D14: 1892.9 | E14: 1859.4 | F14: 2.35M | G14: -0.0066
A15: 06/29/2026 | B15: 1874.8 | C15: 1876.8 | D15: 1897.1 | E15: 1855.9 | F15: 1.66M | G15: 0.0064
A16: 06/25/2026 | B16: 1862.8 | C16: 1870 | D16: 1887 | E16: 1858 | F16: 1.82M | G16: -0.0062
A17: 06/24/2026 | B17: 1874.4 | C17: 1868 | D17: 1882.1 | E17: 1864.9 | F17: 1.41M | G17: 0.0034
A18: 06/23/2026 | B18: 1868 | C18: 1870 | D18: 1902.4 | E18: 1861.2 | F18: 2.81M | G18: 0.0027
A19: 06/22/2026 | B19: 1862.9 | C19: 1845 | D19: 1865.2 | E19: 1834 | F19: 1.59M | G19: 0.0134
A20: 06/19/2026 | B20: 1838.3 | C20: 1824 | D20: 1842.7 | E20: 1820.9 | F20: 2.13M | G20: 0.0074
A21: 06/18/2026 | B21: 1824.8 | C21: 1817.5 | D21: 1830 | E21: 1812.5 | F21: 2.05M | G21: 0.0024
A22: 06/17/2026 | B22: 1820.4 | C22: 1814 | D22: 1823.4 | E22: 1802.6 | F22: 1.77M | G22: 0.0109
A23: 06/16/2026 | B23: 1800.7 | C23: 1808 | D23: 1809.9 | E23: 1792.6 | F23: 1.37M | G23: -0.0029
A24: 06/15/2026 | B24: 1806 | C24: 1818 | D24: 1818 | E24: 1797.8 | F24: 2.19M | G24: -0.0009
A25: 46362 | B25: 1807.7 | C25: 1807 | D25: 1814.5 | E25: 1792.5 | F25: 1.24M | G25: 0.0075
A26: 46332 | B26: 1794.2 | C26: 1780 | D26: 1805 | E26: 1778.7 | F26: 1.86M | G26: 0.0044
A27: 46301 | B27: 1786.4 | C27: 1779.6 | D27: 1797.6 | E27: 1771 | F27: 1.88M | G27: 0.0042
A28: 46271 | B28: 1779 | C28: 1787.7 | D28: 1796.6 | E28: 1766.1 | F28: 3.76M | G28: -0.0055
A29: 46240 | B29: 1788.8 | C29: 1780.7 | D29: 1803.5 | E29: 1773.5 | F29: 3.10M | G29: 0.0037
A30: 46148 | B30: 1782.2 | C30: 1789 | D30: 1802.9 | E30: 1779 | F30: 2.50M | G30: 0.0012
A31: 46118 | B31: 1780.1 | C31: 1787 | D31: 1793.4 | E31: 1768.6 | F31: 2.34M | G31: -0.0047
A32: 46087 | B32: 1788.5 | C32: 1781 | D32: 1796.3 | E32: 1756.8 | F32: 4.21M | G32: -0.0008
A33: 46059 | B33: 1789.9 | C33: 1794.2 | D33: 1800 | E33: 1766.5 | F33: 2.89M | G33: -0.0037
A34: 46028 | B34: 1796.5 | C34: 1812 | D34: 1812.1 | E34: 1777.1 | F34: 2.05M | G34: -0.0015
A35: 05/29/2026 | B35: 1799.2 | C35: 1844.3 | D35: 1852.8 | E35: 1785.3 | F35: 10.06M | G35: -0.0245
A36: 05/27/2026 | B36: 1844.3 | C36: 1865 | D36: 1882 | E36: 1830 | F36: 1.39M | G36: 0.0019
A37: 05/26/2026 | B37: 1840.8 | C37: 1830 | D37: 1844.9 | E37: 1815.9 | F37: 2.34M | G37: 0.0001
A38: 05/25/2026 | B38: 1840.6 | C38: 1840 | D38: 1849 | E38: 1825 | F38: 3.05M | G38: -0.0022
A39: 05/22/2026 | B39: 1844.6 | C39: 1903 | D39: 1903 | E39: 1833.1 | F39: 3.61M | G39: -0.0247
A40: 05/21/2026 | B40: 1891.3 | C40: 1892 | D40: 1899.6 | E40: 1868.1 | F40: 1.61M | G40: 0.0059
...

Sheet HUL
A1: Date | B1: Price | C1: Open | D1: High | E1: Low | F1: Vol. | G1: Change %
A2: 07/16/2026 | B2: 2098.4 | C2: 2104.9 | D2: 2123 | E2: 2096 | F2: 2.14M | G2: -0.002
A3: 07/15/2026 | B3: 2102.6 | C3: 2121 | D3: 2128.5 | E3: 2091 | F3: 2.03M | G3: -0.0083
A4: 07/14/2026 | B4: 2120.2 | C4: 2125 | D4: 2145 | E4: 2116.1 | F4: 2.68M | G4: -0.0049
A5: 07/13/2026 | B5: 2130.6 | C5: 2143 | D5: 2143 | E5: 2120 | F5: 1.83M | G5: -0.0093
A6: 46302 | B6: 2150.6 | C6: 2151.5 | D6: 2178 | E6: 2145 | F6: 1.67M | G6: 0.0028
A7: 46272 | B7: 2144.5 | C7: 2139 | D7: 2166.8 | E7: 2137.1 | F7: 2.20M | G7: 0.0041
A8: 46241 | B8: 2135.8 | C8: 2199 | D8: 2199 | E8: 2130 | F8: 1.33M | G8: -0.033
A9: 46210 | B9: 2208.8 | C9: 2200 | D9: 2219.4 | E9: 2193.7 | F9: 2.55M | G9: 0.0031
A10: 46180 | B10: 2202 | C10: 2202.1 | D10: 2221.4 | E10: 2190.3 | F10: 2.13M | G10: 0.0004
A11: 46088 | B11: 2201.2 | C11: 2224.9 | D11: 2239.3 | E11: 2190 | F11: 1.54M | G11: -0.0043
A12: 46060 | B12: 2210.6 | C12: 2186 | D12: 2216 | E12: 2179.2 | F12: 2.59M | G12: 0.0131
A13: 46029 | B13: 2182 | C13: 2133.5 | D13: 2190 | E13: 2120.2 | F13: 2.50M | G13: 0.0301
A14: 06/30/2026 | B14: 2118.2 | C14: 2151 | D14: 2151.3 | E14: 2114.2 | F14: 2.36M | G14: -0.0154
A15: 06/29/2026 | B15: 2151.3 | C15: 2172 | D15: 2189.9 | E15: 2143 | F15: 1.42M | G15: -0.0105
A16: 06/25/2026 | B16: 2174.2 | C16: 2161 | D16: 2200.9 | E16: 2161 | F16: 1.90M | G16: 0.0076
A17: 06/24/2026 | B17: 2157.8 | C17: 2160 | D17: 2166 | E17: 2140 | F17: 942.27K | G17: -0.0011
A18: 06/23/2026 | B18: 2160.1 | C18: 2160.1 | D18: 2179.7 | E18: 2156 | F18: 710.08K | G18: -0.0114
A19: 06/22/2026 | B19: 2184.9 | C19: 2203.7 | D19: 2208.2 | E19: 2182.5 | F19: 765.86K | G19: -0.0044
A20: 06/19/2026 | B20: 2194.6 | C20: 2209.6 | D20: 2210.6 | E20: 2179.9 | F20: 1.51M | G20: -0.0108
A21: 06/18/2026 | B21: 2218.5 | C21: 2208.7 | D21: 2221.6 | E21: 2196.8 | F21: 1.12M | G21: 0.0095
A22: 06/17/2026 | B22: 2197.6 | C22: 2201.1 | D22: 2224.6 | E22: 2183 | F22: 1.51M | G22: -0.001
A23: 06/16/2026 | B23: 2199.9 | C23: 2161 | D23: 2209 | E23: 2160.1 | F23: 1.34M | G23: 0.0203
A24: 06/15/2026 | B24: 2156.1 | C24: 2200 | D24: 2211 | E24: 2150 | F24: 1.44M | G24: -0.0059
A25: 46362 | B25: 2168.8 | C25: 2151.2 | D25: 2179.4 | E25: 2145 | F25: 1.16M | G25: 0.0136
A26: 46332 | B26: 2139.8 | C26: 2164 | D26: 2165 | E26: 2135.3 | F26: 1.18M | G26: -0.0137
A27: 46301 | B27: 2169.5 | C27: 2134.9 | D27: 2204.9 | E27: 2133.5 | F27: 2.33M | G27: 0.0172
A28: 46271 | B28: 2132.8 | C28: 2119.7 | D28: 2138.6 | E28: 2110.1 | F28: 1.46M | G28: 0.0108
A29: 46240 | B29: 2110.1 | C29: 2105.3 | D29: 2125 | E29: 2091.5 | F29: 1.60M | G29: -0.0054
A30: 46148 | B30: 2121.5 | C30: 2086.7 | D30: 2127.5 | E30: 2077.2 | F30: 1.82M | G30: 0.0202
A31: 46118 | B31: 2079.4 | C31: 2089 | D31: 2110.9 | E31: 2073.5 | F31: 2.14M | G31: -0.0054
A32: 46087 | B32: 2090.6 | C32: 2092 | D32: 2099.6 | E32: 2072.2 | F32: 1.54M | G32: -0.0015
A33: 46059 | B33: 2093.7 | C33: 2079 | D33: 2097 | E33: 2065.7 | F33: 2.15M | G33: 0.0045
A34: 46028 | B34: 2084.3 | C34: 2158.5 | D34: 2167.5 | E34: 2080.3 | F34: 1.47M | G34: -0.0321
A35: 05/29/2026 | B35: 2153.5 | C35: 2133.5 | D35: 2207.8 | E35: 2118.1 | F35: 17.70M | G35: -0.0204
A36: 05/27/2026 | B36: 2198.4 | C36: 2205.1 | D36: 2214.6 | E36: 2187 | F36: 616.54K | G36: -0.005
A37: 05/26/2026 | B37: 2209.4 | C37: 2199.6 | D37: 2220 | E37: 2190 | F37: 2.30M | G37: 0.0059
A38: 05/25/2026 | B38: 2196.5 | C38: 2215 | D38: 2238.1 | E38: 2192.9 | F38: 780.72K | G38: -0.0032
A39: 05/22/2026 | B39: 2203.6 | C39: 2180 | D39: 2224.5 | E39: 2175.4 | F39: 1.38M | G39: 0.0113
A40: 05/21/2026 | B40: 2179 | C40: 2224 | D40: 2229 | E40: 2176 | F40: 1.58M | G40: -0.0137
...

Sheet Infosys
A1: Date | B1: Price | C1: Open | D1: High | E1: Low | F1: Vol. | G1: Change %
A2: 07/16/2026 | B2: 1082.4 | C2: 1082.5 | D2: 1097.3 | E2: 1077.9 | F2: 8.59M | G2: 0.0057
A3: 07/15/2026 | B3: 1076.3 | C3: 1079 | D3: 1088.1 | E3: 1073 | F3: 8.50M | G3: -0.0152
A4: 07/14/2026 | B4: 1092.9 | C4: 1107.8 | D4: 1113.5 | E4: 1090 | F4: 14.82M | G4: -0.0088
A5: 07/13/2026 | B5: 1102.6 | C5: 1057.1 | D5: 1114.9 | E5: 1057.1 | F5: 20.99M | G5: 0.0324
A6: 46302 | B6: 1068 | C6: 1075 | D6: 1091.3 | E6: 1064.7 | F6: 9.75M | G6: 0.0164
A7: 46272 | B7: 1050.8 | C7: 1062.7 | D7: 1062.7 | E7: 1040.4 | F7: 9.00M | G7: -0.0173
A8: 46241 | B8: 1069.3 | C8: 1071.9 | D8: 1079.7 | E8: 1064.4 | F8: 13.02M | G8: -0.0023
A9: 46210 | B9: 1071.8 | C9: 1040.6 | D9: 1087.5 | E9: 1040.6 | F9: 18.87M | G9: 0.0284
A10: 46180 | B10: 1042.2 | C10: 1050.1 | D10: 1053 | E10: 1033 | F10: 5.56M | G10: -0.0048
A11: 46088 | B11: 1047.2 | C11: 1063 | D11: 1068.7 | E11: 1042 | F11: 11.65M | G11: 0.0061
A12: 46060 | B12: 1040.9 | C12: 1006.4 | D12: 1045 | E12: 1006 | F12: 18.74M | G12: 0.0564
A13: 46029 | B13: 985.3 | C13: 1006 | D13: 1014 | E13: 982.4 | F13: 13.04M | G13: -0.0151
A14: 06/30/2026 | B14: 1000.4 | C14: 1030 | D14: 1030.4 | E14: 996 | F14: 24.13M | G14: -0.035
A15: 06/29/2026 | B15: 1036.7 | C15: 1037.1 | D15: 1046.6 | E15: 1029.1 | F15: 15.08M | G15: -0.0043
A16: 06/25/2026 | B16: 1041.2 | C16: 1065 | D16: 1068 | E16: 1039.1 | F16: 15.87M | G16: -0.0146
A17: 06/24/2026 | B17: 1056.6 | C17: 1040.9 | D17: 1065.5 | E17: 1037.7 | F17: 12.35M | G17: 0.0265
A18: 06/23/2026 | B18: 1029.3 | C18: 1053.8 | D18: 1055.3 | E18: 1026 | F18: 19.32M | G18: -0.0339
A19: 06/22/2026 | B19: 1065.4 | C19: 1055 | D19: 1080.3 | E19: 1055 | F19: 10.18M | G19: 0.0133
A20: 06/19/2026 | B20: 1051.4 | C20: 1062.3 | D20: 1066 | E20: 1030 | F20: 45.67M | G20: -0.0675
A21: 06/18/2026 | B21: 1127.5 | C21: 1142.9 | D21: 1142.9 | E21: 1125.3 | F21: 16.78M | G21: -0.0261
A22: 06/17/2026 | B22: 1157.7 | C22: 1149 | D22: 1162.5 | E22: 1148 | F22: 6.00M | G22: 0.0123
A23: 06/16/2026 | B23: 1143.6 | C23: 1136.9 | D23: 1153.8 | E23: 1123.2 | F23: 10.46M | G23: 0.0077
A24: 06/15/2026 | B24: 1134.9 | C24: 1130 | D24: 1151 | E24: 1123 | F24: 7.86M | G24: 0.0166
A25: 46362 | B25: 1116.4 | C25: 1120 | D25: 1123.3 | E25: 1111.5 | F25: 8.08M | G25: 0.0016
A26: 46332 | B26: 1114.6 | C26: 1129.7 | D26: 1133.7 | E26: 1109 | F26: 9.37M | G26: -0.0268
A27: 46301 | B27: 1145.3 | C27: 1160.1 | D27: 1171.4 | E27: 1143.3 | F27: 8.89M | G27: -0.0297
A28: 46271 | B28: 1180.3 | C28: 1193.6 | D28: 1193.6 | E28: 1167.3 | F28: 10.98M | G28: -0.0061
A29: 46240 | B29: 1187.6 | C29: 1177.5 | D29: 1200.7 | E29: 1176.5 | F29: 8.63M | G29: -0.0083
A30: 46148 | B30: 1197.5 | C30: 1220 | D30: 1223.8 | E30: 1194.3 | F30: 8.69M | G30: -0.0032
A31: 46118 | B31: 1201.3 | C31: 1208 | D31: 1215.2 | E31: 1196.2 | F31: 12.76M | G31: -0.0174
A32: 46087 | B32: 1222.6 | C32: 1242.1 | D32: 1249.9 | E32: 1216 | F32: 18.53M | G32: -0.0379
A33: 46059 | B33: 1270.8 | C33: 1232.5 | D33: 1278.9 | E33: 1232.5 | F33: 36.03M | G33: 0.0568
A34: 46028 | B34: 1202.5 | C34: 1175 | D34: 1217 | E34: 1173.7 | F34: 19.44M | G34: 0.0358
A35: 05/29/2026 | B35: 1160.9 | C35: 1182 | D35: 1210 | E35: 1153.6 | F35: 69.09M | G35: 0.0009
A36: 05/27/2026 | B36: 1159.9 | C36: 1161 | D36: 1167.3 | E36: 1155 | F36: 6.37M | G36: -0.0067
A37: 05/26/2026 | B37: 1167.7 | C37: 1166.3 | D37: 1180.7 | E37: 1162.9 | F37: 8.01M | G37: -0.0007
A38: 05/25/2026 | B38: 1168.5 | C38: 1183 | D38: 1185 | E38: 1166.1 | F38: 5.86M | G38: -0.0051
A39: 05/22/2026 | B39: 1174.5 | C39: 1182.5 | D39: 1191.8 | E39: 1172.5 | F39: 8.80M | G39: -0.0057
A40: 05/21/2026 | B40: 1181.2 | C40: 1196.1 | D40: 1201.8 | E40: 1177 | F40: 10.02M | G40: -0.0105
...

Sheet HDFC Bank
A1: Date | B1: Price | C1: Open | D1: High | E1: Low | F1: Vol. | G1: Change %
A2: 07/16/2026 | B2: 808.3 | C2: 814.5 | D2: 818 | E2: 806.5 | F2: 18.70M | G2: -0.0088
A3: 07/15/2026 | B3: 815.45 | C3: 811 | D3: 819.7 | E3: 809.7 | F3: 21.49M | G3: 0.0075
A4: 07/14/2026 | B4: 809.4 | C4: 811.4 | D4: 818.4 | E4: 807 | F4: 25.61M | G4: -0.0105
A5: 07/13/2026 | B5: 817.95 | C5: 817 | D5: 821.95 | E5: 811 | F5: 21.74M | G5: -0.0085
A6: 46302 | B6: 824.95 | C6: 824 | D6: 827.7 | E6: 820.3 | F6: 23.60M | G6: 0.0091
A7: 46272 | B7: 817.55 | C7: 813 | D7: 822.85 | E7: 812.3 | F7: 39.89M | G7: 0.0089
A8: 46241 | B8: 810.3 | C8: 825.9 | D8: 834.35 | E8: 806.95 | F8: 38.75M | G8: -0.0229
A9: 46210 | B9: 829.3 | C9: 843 | D9: 843 | E9: 826.1 | F9: 57.61M | G9: -0.0007
A10: 46180 | B10: 829.85 | C10: 805 | D10: 831.5 | E10: 805 | F10: 63.20M | G10: 0.036
A11: 46088 | B11: 801.05 | C11: 803 | D11: 807 | E11: 798.55 | F11: 25.87M | G11: 0.0065
A12: 46060 | B12: 795.9 | C12: 795 | D12: 805.45 | E12: 794 | F12: 34.14M | G12: -0.0003
A13: 46029 | B13: 796.15 | C13: 793.5 | D13: 802.25 | E13: 793.5 | F13: 26.09M | G13: -0.0023
A14: 06/30/2026 | B14: 797.95 | C14: 806.1 | D14: 806.1 | E14: 792.75 | F14: 45.78M | G14: -0.0012
A15: 06/29/2026 | B15: 798.9 | C15: 800 | D15: 805.9 | E15: 793.3 | F15: 46.70M | G15: 0.0033
A16: 06/25/2026 | B16: 796.3 | C16: 798.5 | D16: 804.45 | E16: 794.75 | F16: 46.71M | G16: 0.0039
A17: 06/24/2026 | B17: 793.2 | C17: 773 | D17: 794.9 | E17: 772.65 | F17: 34.70M | G17: 0.0239
A18: 06/23/2026 | B18: 774.65 | C18: 783.05 | D18: 790.9 | E18: 772.55 | F18: 28.29M | G18: -0.0149
A19: 06/22/2026 | B19: 786.4 | C19: 789.9 | D19: 789.9 | E19: 783.1 | F19: 25.19M | G19: 0.0085
A20: 06/19/2026 | B20: 779.8 | C20: 788.7 | D20: 789.05 | E20: 776.2 | F20: 33.80M | G20: -0.024
A21: 06/18/2026 | B21: 799 | C21: 786.5 | D21: 802.95 | E21: 786.2 | F21: 41.49M | G21: 0.0151
A22: 06/17/2026 | B22: 787.1 | C22: 787.65 | D22: 794.3 | E22: 783.1 | F22: 32.41M | G22: 0.0028
A23: 06/16/2026 | B23: 784.9 | C23: 780.5 | D23: 787.7 | E23: 779.45 | F23: 27.82M | G23: 0.0097
A24: 06/15/2026 | B24: 777.35 | C24: 790 | D24: 793.5 | E24: 775.6 | F24: 39.99M | G24: 0.0063
A25: 46362 | B25: 772.45 | C25: 754.7 | D25: 774.45 | E25: 753.1 | F25: 36.09M | G25: 0.0374
A26: 46332 | B26: 744.6 | C26: 743 | D26: 756 | E26: 740.1 | F26: 32.63M | G26: -0.003
A27: 46301 | B27: 746.85 | C27: 736.5 | D27: 755.95 | E27: 736.4 | F27: 44.46M | G27: 0.0115
A28: 46271 | B28: 738.35 | C28: 739.45 | D28: 743.95 | E28: 732.3 | F28: 38.54M | G28: -0.0004
A29: 46240 | B29: 738.65 | C29: 738 | D29: 741.5 | E29: 734.5 | F29: 21.55M | G29: -0.0112
A30: 46148 | B30: 747.05 | C30: 753.95 | D30: 758.7 | E30: 744.65 | F30: 22.12M | G30: -0.0095
A31: 46118 | B31: 754.2 | C31: 749.15 | D31: 757.3 | E31: 745 | F31: 42.67M | G31: 0.0007
A32: 46087 | B32: 753.65 | C32: 744.45 | D32: 756.9 | E32: 742.6 | F32: 36.11M | G32: 0.0072
A33: 46059 | B33: 748.25 | C33: 737 | D33: 753.6 | E33: 733.15 | F33: 47.31M | G33: 0.0075
A34: 46028 | B34: 742.7 | C34: 749 | D34: 752.35 | E34: 739.2 | F34: 48.00M | G34: -0.0025
A35: 05/29/2026 | B35: 744.55 | C35: 746.05 | D35: 760.5 | E35: 737.75 | F35: 101.30M | G35: -0.0186
A36: 05/27/2026 | B36: 758.65 | C36: 769.5 | D36: 773.9 | E36: 756.9 | F36: 63.68M | G36: -0.026
A37: 05/26/2026 | B37: 778.9 | C37: 784.05 | D37: 790.85 | E37: 776.75 | F37: 31.53M | G37: -0.0101
A38: 05/25/2026 | B38: 786.85 | C38: 776 | D38: 787.85 | E38: 775.2 | F38: 26.04M | G38: 0.0261
A39: 05/22/2026 | B39: 766.8 | C39: 759.15 | D39: 775 | E39: 759.15 | F39: 25.60M | G39: 0.0101
A40: 05/21/2026 | B40: 759.15 | C40: 767 | D40: 768.25 | E40: 755.15 | F40: 34.66M | G40: -0.0005
...

Sheet Nifty 50
A1: Date | B1: Price | C1: Open | D1: High | E1: Low | F1: Vol. | G1: Change %
A2: 07/16/2026 | B2: 24072.75 | C2: 24142.1 | D2: 24185.9 | E2: 24052.35 | F2: 264.27M | G2: -0.0002
A3: 07/15/2026 | B3: 24078.5 | C3: 24085.85 | D3: 24220.35 | E3: 24010.55 | F3: 306.92M | G3: 0.0011
A4: 07/14/2026 | B4: 24052.05 | C4: 24068 | D4: 24157.1 | E4: 24023.7 | F4: 355.83M | G4: -0.0066
A5: 07/13/2026 | B5: 24211 | C5: 24039.4 | D5: 24259.8 | E5: 24000.2 | F5: 322.68M | G5: 0.0002
A6: 46302 | B6: 24206.9 | C6: 24124.7 | D6: 24228.45 | E6: 24120.35 | F6: 313.07M | G6: 0.0102
A7: 46272 | B7: 23962.8 | C7: 23928.95 | D7: 24134.7 | E7: 23925.7 | F7: 384.80M | G7: 0.0034
A8: 46241 | B8: 23882.05 | C8: 24259.55 | D8: 24300 | E8: 23805.2 | F8: 420.53M | G8: -0.0212
A9: 46210 | B9: 24398.7 | C9: 24464.45 | D9: 24530.9 | E9: 24348.95 | F9: 412.62M | G9: -0.0013
A10: 46180 | B10: 24430.35 | C10: 24306.85 | D10: 24458.65 | E10: 24287.1 | F10: 329.36M | G10: 0.0066
A11: 46088 | B11: 24270.85 | C11: 24375.65 | D11: 24378.15 | E11: 24252.35 | F11: 326.63M | G11: 0.0039
A12: 46060 | B12: 24175.7 | C12: 24062.2 | D12: 24194.55 | E12: 24058.8 | F12: 372.94M | G12: 0.0071
A13: 46029 | B13: 24005.85 | C13: 23897.65 | D13: 24049.9 | E13: 23895.1 | F13: 352.15M | G13: 0.0059
A14: 06/30/2026 | B14: 23865.75 | C14: 24032.05 | D14: 24035.55 | E14: 23829.2 | F14: 449.04M | G14: -0.0034
A15: 06/29/2026 | B15: 23946.25 | C15: 24061.75 | D15: 24120 | E15: 23924.55 | F15: 588.50M | G15: -0.0046
A16: 06/25/2026 | B16: 24056 | C16: 24125.85 | D16: 24261.6 | E16: 24039 | F16: 448.75M | G16: 0.0014
A17: 06/24/2026 | B17: 24021.65 | C17: 23795.8 | D17: 24090.05 | E17: 23789.25 | F17: 395.58M | G17: 0.0083
A18: 06/23/2026 | B18: 23824.1 | C18: 24071.3 | D18: 24135.5 | E18: 23784.95 | F18: 340.09M | G18: -0.0116
A19: 06/22/2026 | B19: 24102.9 | C19: 24106.6 | D19: 24168.05 | E19: 24073.15 | F19: 252.82M | G19: 0.0037
A20: 06/19/2026 | B20: 24013.1 | C20: 23991.2 | D20: 24047.2 | E20: 23901.9 | F20: 447.86M | G20: -0.0064
A21: 06/18/2026 | B21: 24168 | C21: 24073.8 | D21: 24189.25 | E21: 24036.95 | F21: 339.99M | G21: 0.0034
A22: 06/17/2026 | B22: 24085.7 | C22: 24044.5 | D22: 24108.2 | E22: 23969.7 | F22: 352.67M | G22: 0.004
A23: 06/16/2026 | B23: 23989.15 | C23: 23923.9 | D23: 24002.6 | E23: 23888.2 | F23: 327.31M | G23: 0.0057
A24: 06/15/2026 | B24: 23853.9 | C24: 23984.85 | D24: 24011.4 | E24: 23817.8 | F24: 398.91M | G24: 0.0098
A25: 46362 | B25: 23622.9 | C25: 23412.55 | D25: 23645.35 | E25: 23313.9 | F25: 351.94M | G25: 0.0199
A26: 46332 | B26: 23161.6 | C26: 23104.4 | D26: 23327.45 | E26: 23072.05 | F26: 363.00M | G26: -0.0023
A27: 46301 | B27: 23214.95 | C27: 23233.95 | D27: 23425.35 | E27: 23184.6 | F27: 380.03M | G27: -0.0012
A28: 46271 | B28: 23242.1 | C28: 23259.05 | D28: 23279.4 | E28: 23104.45 | F28: 402.55M | G28: 0.0052
A29: 46240 | B29: 23123 | C29: 23080.7 | D29: 23267.3 | E29: 23070.15 | F29: 375.73M | G29: -0.0104
A30: 46148 | B30: 23366.7 | C30: 23478.95 | D30: 23516.35 | E30: 23282.65 | F30: 366.21M | G30: -0.0021
A31: 46118 | B31: 23416.55 | C31: 23282.45 | D31: 23465.3 | E31: 23247.3 | F31: 412.51M | G31: 0.0005
A32: 46087 | B32: 23405.6 | C32: 23415.95 | D32: 23459.65 | E32: 23151.5 | F32: 450.08M | G32: -0.0033
A33: 46059 | B33: 23483.55 | C33: 23229.15 | D33: 23556.95 | E33: 23229.15 | F33: 511.85M | G33: 0.0043
A34: 46028 | B34: 23382.6 | C34: 23654.5 | D34: 23733.7 | E34: 23357.95 | F34: 421.69M | G34: -0.007
A35: 05/29/2026 | B35: 23547.75 | C35: 23902.15 | D35: 24002.8 | E35: 23484.75 | F35: 1.20B | G35: -0.015
A36: 05/27/2026 | B36: 23907.15 | C36: 23880.35 | D36: 23983.2 | E36: 23858.25 | F36: 531.57M | G36: -0.0003
A37: 05/26/2026 | B37: 23913.7 | C37: 24004.1 | D37: 24089.8 | E37: 23885.45 | F37: 387.93M | G37: -0.0049
A38: 05/25/2026 | B38: 24031.7 | C38: 23940.25 | D38: 24054.45 | E38: 23922.85 | F38: 351.22M | G38: 0.0132
A39: 05/22/2026 | B39: 23719.3 | C39: 23671.2 | D39: 23835.65 | E39: 23671 | F39: 336.11M | G39: 0.0027
A40: 05/21/2026 | B40: 23654.7 | C40: 23830.05 | D40: 23859.9 | E40: 23596.6 | F40: 348.18M | G40: -0.0002
...
